Workbook
Name Group1: 'H22'!$C$8:$C$29
Name Last7: OFFSET('H36'!$C$8,COUNTA('H36'!$C:$C)-7-1,0,7,1)

Sheet H1
B7: Mes | C7: Ventas por Mes
B8: Enero | C8: 186983
B9: Febrero | C9: 179009
B10: Marzo | C10: 193422
B11: Abril | C11: 185956
B12: Mayo | C12: 196025
B13: Junio | C13: 140323
B14: Julio | C14: 139302
B15: Agosto | C15: 134922
B16: Septiembre | C16: 184773
B17: Octubre | C17: 201233
B18: Noviembre | C18: 218039
B19: Diciembre | C19: 240093

Sheet H2
B7: Año | C7: Area 1 | D7: Area 2
B8: 2001 | C8: 214000 | D8: 356879
B9: 2002 | C9: 247250 | D9: 385070
B10: 2003 | C10: 277500 | D10: 42600 | P10: VERTICAL (EJE Y)
B11: 2004 | C11: 374500 | D11: 520000
B12: 2005 | C12: 435000 | D12: 725000
B13: 2006 | C13: 489500 | D13: 820000
B14: 2007 | C14: 480500 | D14: 759000
B15: 2008 | C15: 401700 | D15: 702300
B16: 2009 | C16: 302500 | D16: 589000
R19: HORIZONTAL (X)

Sheet H3
B7: Mes | C7: Visitantes del sitio web
B8: Enero | C8: 319300
B9: Febrero | C9: 292600
B10: March | C10: 339630 | N10: OBJETO NO VOLÁTIL
B11: April | C11: 321960 | N11: 100
B12: May | C12: 397854
B13: June | C13: 321960

Sheet H4
B7: Mes | C7: Ingreso | D7: Ganancia Ganancia
B8: Enero | C8: 151032 | D8: 0.093
B9: Febrero | C9: 187933 | D9: 0.112
B10: Marzo | C10: 146301 | D10: 0.108
B11: Abril | C11: 153978 | D11: 0.096 | U11: Pestaña Contextual
B12: Mayo | C12: 189331 | D12: 0.095
B13: Junio | C13: 157323 | D13: 0.11

Sheet H5
B7: Estado | C7: No.
B8: Casados | C8: 24
B9: Solteros | C9: 26
B10: Divorciados | C10: 23
B11: Viudos | C11: 27

Sheet H6
B7: Mes | C7: No.
B8: Enero | C8: 389
B9: Febrero | C9: 483 | P9: Cantidad de datos
B10: Marzo | C10: 522 | P10: Tipo de gráfico
B11: Abril | C11: 684 | P11: Diseño del gráfico
B12: Mayo | C12: 733
B13: Junio | C13: 892

Sheet H7
B7: Mes | C7: Proyectado | D7: Actual
B8: Ene | C8: 2000 | D8: 1895
B9: Feb | C9: 2500 | D9: 2643
B10: Mar | C10: 3500 | D10: 3648

Sheet H8

Sheet H9
B7: Mes | C7: Visitantes
B8: Enero | C8: 7092
B9: Feb | C9: 7497
B10: Mar | C10: 7560
B11: Abr | C11: 5796
B12: May | C12: 13984
B13: Jun | C13: 18743
B14: Jul | C14: 15434
B15: Ago | C15: 14545
B16: Septiembre | C16: 17434
B17: Oct | C17: 16984
B18: Nov | C18: 15983
B19: Dic | C19: 27822

Sheet H10
B7: Mes | C7: Widgets | D7: Sprockets
B8: 2 | C8: 60983 | D8: 64983
B9: Feb | C9: 56732 | D9: 68981
B10: Mar | C10: 49831 | D10: 77398
B11: Abr | C11: 43323 | D11: 88091
B12: May | C12: 39879 | D12: 93733

Sheet H11
B7: Item | C7: Totalmente de acuerdo | D7: Aceptación | E7: Indeciso | F7: En desacuerdo | G7: Totalmente en desacuerdo
B8: Los empleados son amigables | C8: 0.02 | D8: 0.06 | E8: 0.32 | F8: 0.43 | G8: 0.17
B9: Recomendaría su empresa | C9: 0.03 | D9: 0.09 | E9: 0.2 | F9: 0.27 | G9: 0.41
B10: Me gustan tus anuncios de televisión | C10: 0.05 | D10: 0.09 | E10: 0.32 | F10: 0.38 | G10: 0.16
B11: En general estoy satisfecho | C11: 0.06 | D11: 0.28 | E11: 0.24 | F11: 0.25 | G11: 0.17
B12: Las tiendas están bien mantenidas | C12: 0.09 | D12: 0.11 | E12: 0.32 | F12: 0.31 | G12: 0.17
B13: Las ubicaciones de las tiendas son convenientes | C13: 0.12 | D13: 0.14 | E13: 0.21 | F13: 0.21 | G13: 0.32
B14: El horario de la tienda es conveniente | C14: 0.15 | D14: 0.18 | E14: 0.24 | F14: 0.29 | G14: 0.14
B15: Tienes una buena selección de productos | C15: 0.16 | D15: 0.19 | E15: 0.32 | F15: 0.21 | G15: 0.12
B16: Me gusta tu sitio web | C16: 0.18 | D16: 0.32 | E16: 0.32 | F16: 0.12 | G16: 0.08
B17: Vendes productos de calidad | C17: 0.24 | D17: 0.21 | E17: 0.28 | F17: 0.15 | G17: 0.12

Sheet H12
B7: Fecha | C7: Viviendas iniciadas | O7: Empleados por región | AB7: Proyecciones de población (en miles)
B8: 21551 | C8: 1657000
B9: 21582 | C9: 1667000 | O9: Año | P9: West | Q9: Mid | R9: East | AB9: Año | AC9: California | AD9: Oregon | AE9: Washington
B10: 21610 | C10: 1620000 | O10: 2011 | P10: 108 | R10: 201 | AB10: 1995 | AC10: 31589 | AD10: 3141 | AE10: 5431
B11: 21641 | C11: 1590000 | O11: 2012 | P11: 121 | R11: 222 | AB11: 2000 | AC11: 32521 | AD11: 3397 | AE11: 5858
B12: 21671 | C12: 1498000 | O12: 2013 | P12: 136 | Q12: 32 | R12: 183 | AB12: 2005 | AC12: 34441 | AD12: 3613 | AE12: 6258
B13: 21702 | C13: 1503000 | O13: 2014 | P13: 208 | Q13: 87 | R13: 143 | AB13: 2015 | AC13: 41373 | AD13: 3992 | AE13: 7058
B14: 21732 | C14: 1547000 | O14: 2015 | P14: 312 | Q14: 90 | R14: 140 | AB14: 2025 | AC14: 49285 | AD14: 4349 | AE14: 7808
B15: 21763 | C15: 1430000
B16: 21794 | C16: 1540000
B17: 21824 | C17: 1355000
B18: 21855 | C18: 1416000
B19: 21885 | C19: 1601000
B20: 21916 | C20: 1460000
B21: 21947 | C21: 1503000
B22: 21976 | C22: 1109000
B23: 22007 | C23: 1289000
B24: 22037 | C24: 1271000
B25: 22068 | C25: 1247000
B26: 22098 | C26: 1197000
... B683: 42095 | C683: 1135000

Sheet H13
B7: Version | C7: Numero de Usuarios | L7: Categoria | M7: Cantidad
B8: Excel 2019 | C8: 183 | L8: Renta | M8: 12909288
B9: Excel 2016 | C9: 981 | L9: Suministros | M9: 3221904
B10: Excel 2013 | C10: 612 | L10: Utilidades | M10: 2981448
B11: Excel 2010 | C11: 283 | L11: Salario Región 1 | M11: 7832288
L12: Salario Región 2 | M12: 1959768
L13: Salario Región 3 | M13: 3983233
L14: Salario Región 4 | M14: 2887309

Sheet H14
C7: Producto A | D7: Producto B | E7: Producto C
B8: Qtr-1 | C8: 474 | D8: 1243 | E8: 564
B9: Qtr-2 | C9: 732 | D9: 902 | E9: 455
B10: Qtr-3 | C10: 897 | D10: 621 | E10: 233
B11: Qtr-4 | C11: 977 | D11: 1345 | E11: 565

Sheet H15
B7: Month | C7: Ventas de esquí de nieve | D7: Venta de esquí acuático
B8: Ene | C8: 6897 | D8: 1983
B9: Feb | C9: 7732 | D9: 5547
B10: Mar | C10: 4500 | D10: 7330
B11: Abr | C11: 3122 | D11: 9832
B12: May | C12: 893 | D12: 10739
B13: Jun | C13: 734 | D13: 16453
B14: Jul | C14: 891 | D14: 15874
B15: Ago | C15: 559 | D15: 9833
B16: Sep | C16: 5433 | D16: 3244
B17: Oct | C17: 8734 | D17: 2873
B18: Nov | C18: 11873 | D18: 3459
B19: Dic | C19: 18730 | D19: 5433

Sheet H16
B7: Participantes | C7: Peso original | D7: Semanas en Programa | E7: Peso Pérdida
B8: Ray | C8: 285 | D8: 12 | E8: 31
B9: Pat | C9: 442 | D9: 3 | E9: 16
B10: Jill | C10: 240 | D10: 5 | E10: 28
B11: George | C11: 275 | D11: 18 | E11: 34
B12: Kevin | C12: 290 | D12: 2 | E12: 4
B13: Joe | C13: 380 | D13: 18 | E13: 15
B14: Cindy | C14: 188 | D14: 13 | E14: 13
B15: Terry | C15: 301 | D15: 7 | E15: 32

Sheet H17
C7: Volumen | D7: Abierto | E7: Alta | F7: Bajo | G7: Cerrado
B8: 38922 | C8: 12155 | D8: 69.805 | E8: 72.625 | F8: 69.688 | G8: 70.5
B9: =B8+1 -> 38923 | C9: 14555 | D9: 70.938 | E9: 74 | F9: 70.719 | G9: 73.25
B10: =B9+1 -> 38924 | C10: 11983 | D10: 74.75 | E10: 75.75 | F10: 73.375 | G10: 75.625
B11: =B10+1 -> 38925 | C11: 14877 | D11: 74.875 | E11: 75.312 | F11: 74.125 | G11: 75.25
B12: =B11+1 -> 38926 | C12: 16983 | D12: 76.094 | E12: 76.375 | F12: 73.5 | G12: 74.938

Sheet H18
B7: Datos de temperatura de mayo
C9: Alto | D9: Baja | E9: Promedio
B10: 1 | C10: 74 | D10: 50 | E10: =AVERAGE(C10:D10) -> 62
B11: 2 | C11: 70 | D11: 52 | E11: =AVERAGE(C11:D11) -> 61
B12: 3 | C12: 72 | D12: 56 | E12: =AVERAGE(C12:D12) -> 64
B13: 4 | C13: 66 | D13: 50 | E13: =AVERAGE(C13:D13) -> 58
B14: 5 | C14: 61 | D14: 53 | E14: =AVERAGE(C14:D14) -> 57
B15: 6 | C15: 59 | D15: 48 | E15: =AVERAGE(C15:D15) -> 53.5
B16: 7 | C16: 73 | D16: 51 | E16: =AVERAGE(C16:D16) -> 62
B17: 8 | C17: 72 | D17: 53 | E17: =AVERAGE(C17:D17) -> 62.5
B18: 9 | C18: 70 | D18: 56 | E18: =AVERAGE(C18:D18) -> 63
B19: 10 | C19: 73 | D19: 60 | E19: =AVERAGE(C19:D19) -> 66.5
B20: 11 | C20: 79 | D20: 60 | E20: =AVERAGE(C20:D20) -> 69.5
B21: 12 | C21: 82 | D21: 62 | E21: =AVERAGE(C21:D21) -> 72
... B40: 31 | C40: 71 | D40: 62 | E40: =AVERAGE(C40:D40) -> 66.5

Sheet H19
B7: Estudiante | C7: Puntaje
B8: Michael Miller | C8: 43
B9: Earnest Williams | C9: 76
B10: Mary Ford | C10: 56
B11: Karen P. Perez | C11: 71
B12: Stephen Nelson | C12: 65
B13: Hope Barnett | C13: 61
B14: Robert Melton | C14: 64
B15: Virginia Martinez | C15: 58
B16: John Perez | C16: 68
B17: Susan Willis | C17: 84
B18: Gregory Austin | C18: 51
B19: Patricia Tucker | C19: 82
... B112: Margaret Moore | C112: 67

Sheet H20
B7: Queja | C7: Número
B8: No me gustó la comida | C8: 15
B9: Difícil de encontrar | C9: 3
B10: Baños sucios | C10: 33
B11: La comida estaba fría | C11: 6
B12: Falta de estacionamiento | C12: 12
B13: Menú limitado | C13: 8
B14: Larga espera para sentarse. | C14: 13
B15: Larga espera para ser atendido. | C15: 18
B16: Recibí comida equivocada | C16: 4
B17: Personal grosero | C17: 27
B18: Demasiado caro | C18: 23
B19: Demasiado ruidoso | C19: 37

Sheet H21
B7: Mes | C7: Ingreso | D7: Gastos | E7: Neto | O7: Mes | P7: Neto acumulado
B8: Ene | C8: 10833 | D8: 8982 | E8: ='H21'!$C8-'H21'!$D8 -> 1851 | O8: Ene | P8: ='H21'!$E8 -> 1851
B9: Feb | C9: 12252 | D9: 10232 | E9: ='H21'!$C9-'H21'!$D9 -> 2020 | O9: Feb | P9: =P8+'H21'!$E9 -> 3871
B10: Mar | C10: 12018 | D10: 11116 | E10: ='H21'!$C10-'H21'!$D10 -> 902 | O10: Mar | P10: =P9+'H21'!$E10 -> 4773
B11: Abr | C11: 12928 | D11: 10639 | E11: ='H21'!$C11-'H21'!$D11 -> 2289 | O11: Abr | P11: =P10+'H21'!$E11 -> 7062
B12: May | C12: 13011 | D12: 11597 | E12: ='H21'!$C12-'H21'!$D12 -> 1414 | O12: May | P12: =P11+'H21'!$E12 -> 8476
B13: Jun | C13: 11835 | D13: 12432 | E13: ='H21'!$C13-'H21'!$D13 -> -597 | O13: Jun | P13: =P12+'H21'!$E13 -> 7879
B14: Jul | C14: 10642 | D14: 11838 | E14: ='H21'!$C14-'H21'!$D14 -> -1196 | O14: Jul | P14: =P13+'H21'!$E14 -> 6683
B15: Ago | C15: 10954 | D15: 12696 | E15: ='H21'!$C15-'H21'!$D15 -> -1742 | O15: Ago | P15: =P14+'H21'!$E15 -> 4941
B16: Sep | C16: 12065 | D16: 14355 | E16: ='H21'!$C16-'H21'!$D16 -> -2290 | O16: Sep | P16: =P15+'H21'!$E16 -> 2651
B17: Oct | C17: 12505 | D17: 11833 | E17: ='H21'!$C17-'H21'!$D17 -> 672 | O17: Oct | P17: =P16+'H21'!$E17 -> 3323
B18: Nov | C18: 13611 | D18: 11374 | E18: ='H21'!$C18-'H21'!$D18 -> 2237 | O18: Nov | P18: =P17+'H21'!$E18 -> 5560
B19: Dic | C19: 14364 | D19: 11787 | E19: ='H21'!$C19-'H21'!$D19 -> 2577 | O19: Dic | P19: =P18+'H21'!$E19 -> 8137
B20: Total | C20: =SUBTOTAL(109,'H21'!$C$8:$C$19) -> 147018 | D20: =SUBTOTAL(109,'H21'!$D$8:$D$19) -> 138881 | E20: =SUBTOTAL(109,'H21'!$E$8:$E$19) -> 8137

Sheet H22
B7: Número de grupo | C7: Puntaje | M7: Cálculos del grupo 1 como referencia.
B8: Placebo | C8: 1664 | M8: Min | N8: =MIN(Group1) -> 544
B9: Placebo | C9: 1084 | M9: Max | N9: =MAX(Group1) -> 2458
B10: Placebo | C10: 1780 | M10: 25th percentile | N10: =_xlfn.PERCENTILE.EXC(Group1,0.25) -> 1070.75
B11: Placebo | C11: 2321 | M11: 50th percentile (median) | N11: =_xlfn.PERCENTILE.EXC(Group1,0.5) -> 1813.5
B12: Placebo | C12: 921 | M12: 75th percentile | N12: =_xlfn.PERCENTILE.EXC(Group1,0.75) -> 2149.5
B13: Placebo | C13: 2402 | M13: Medio | N13: =AVERAGE(Group1) -> 1650.3636
B14: Placebo | C14: 2253
B15: Placebo | C15: 2458 | L15: ¿Qué es la desviación estándar?
B16: Placebo | C16: 1031
B17: Placebo | C17: 2101 | L17: 5
B18: Placebo | C18: 667 | L18: 5
B19: Placebo | C19: 652 | L19: 7
B20: Placebo | C20: 1380 | L20: 5
B21: Placebo | C21: 1961 | L21: 3
B22: Placebo | C22: 1794 | L22: 7
B23: Placebo | C23: 1833 | L23: 20
B24: Placebo | C24: 2059 | L24: =STDEV(L17:L23) -> 5.7113087
B25: Placebo | C25: 544 | L25: =AVERAGE(L17:L23) -> 7.4285714
B26: Placebo | C26: 2254
B27: Placebo | C27: 2115
B28: Placebo | C28: 1943
B29: Placebo | C29: 1091
B30: Tratamiento A | C30: 2646
B31: Tratamiento A | C31: 2465
B32: Tratamiento A | C32: 912
B33: Tratamiento A | C33: 2575
B34: Tratamiento A | C34: 1154
B35: Tratamiento A | C35: 1093
B36: Tratamiento A | C36: 2552
B37: Tratamiento A | C37: 1472
... B101: Tratamiento C | C101: 1559

Sheet H23
B7: Género | C7: Sub-Género | D7: Tracks
B8: Bluegrass | D8: 1281
B9: Blues | C9: Acoustic | D9: 1815
C10: Electric | D10: 2460
B11: Cajun & Zydeco | D11: 464
B12: Classical | D12: 882
B13: Country | C13: Classic | D13: 2192
C14: Female | D14: 1247
C15: Male | D15: 2495
C16: Western | D16: 365
B17: Electronic | D17: 1860
B18: Folk | C18: Female | D18: 2551
C19: Male | D19: 3616
B20: Hawaiian | D20: 659
B21: Instructional | D21: 913
B22: Jazz | C22: Instrumental | D22: 2688
C23: Vocal | D23: 3455
C24: Smooth Jazz
B25: New Age | D25: 1933
B26: Old Time | C26: Stringband | D26: 8616
C27: Banjo | D27: 2359
B28: Oldies | D28: 402
B29: Pop | C29: Female | D29: 2382
C30: Male | D30: 6124
B31: R&B | C31: Classic | D31: 1472
C32: Modern | D32: 1183
B33: Rap | D33: 90
B34: Reggae | D34: 1863
B35: Rock | D35: 1377
B36: Soundtracks | D36: 2095
B37: Swing | D37: 105
B38: Theme Time Radio Hour | D38: 2795
B39: World | D39: 2573
B40: Novelty | D40: 969

Sheet H24
B7: Genre | C7: Sub-Genre | D7: Tracks
B8: Bluegrass | D8: 1281
B9: Blues | C9: Acoustic | D9: 1815
C10: Electric | D10: 2460
B11: Cajun & Zydeco | D11: 464
B12: Classical | D12: 882
B13: Country | C13: Classic | D13: 2192
C14: Female | D14: 1247
C15: Male | D15: 2495
C16: Western | D16: 365
B17: Electronic | D17: 1860
B18: Folk | C18: Female | D18: 2551
C19: Male | D19: 3616
B20: Hawaiian | D20: 659
B21: Instructional | D21: 913
B22: Jazz | C22: Instrumental | D22: 2688
C23: Vocal | D23: 3455
C24: Smooth Jazz
B25: New Age | D25: 1933
B26: Old Time | C26: Stringband | D26: 8616
C27: Banjo | D27: 2359
B28: Oldies | D28: 402
B29: Pop | C29: Female | D29: 2382
C30: Male | D30: 6124
B31: R&B | C31: Classic | D31: 1472
C32: Modern | D32: 1183
B33: Rap | D33: 90
B34: Reggae | D34: 1863
B35: Rock | D35: 1377
B36: Soundtracks | D36: 2095
B37: Swing | D37: 105
B38: Theme Time Radio Hour | D38: 2795
B39: World | D39: 2573
B40: Novelty | D40: 969

Sheet H25
B6: Nivel | C6: $
B7: Leads | C7: 3300000
B8: Estimate | C8: 1500000
B9: Oportunity | C9: 950000
B10: Hot Sale | C10: 540000
B11: Closed | C11: 340000

Sheet H26
B6: País | C6: # de teléfonos celulares
B7: China | C7: 1321930000
B8: India | C8: 1183408611
B9: United States | C9: 327577529
B10: Brazil | C10: 284200000
B11: Russia | C11: 256116000
B12: Indonesia | C12: 236800000
B13: Nigeria | C13: 167371945
B14: Japan | C14: 146649600
B15: Pakistan | C15: 150169643
B16: Bangladesh | C16: 131376000
B17: Germany | C17: 107000000
B18: Philippines | C18: 106987098
... B80: Maldives | C80: 776716

Sheet H27
B7: Month | C7: Ventas proyectadas | L7: Employees by Region
B8: Jan | C8: 50000
B9: Feb | C9: =C8*103.5% -> 51750 | M9: West | N9: Mid | O9: East
B10: Mar | C10: =C9*103.5% -> 53561.25 | L10: 2011 | M10: 108 | O10: 201
B11: Apr | C11: =C10*103.5% -> 55435.894 | L11: 2012 | M11: 121 | O11: 222
B12: May | C12: =C11*103.5% -> 57376.15 | L12: 2013 | M12: 136 | N12: 32 | O12: 183
B13: Jun | C13: =C12*103.5% -> 59384.315 | L13: 2014 | M13: 208 | N13: 87 | O13: 143
B14: Jul | C14: =C13*103.5% -> 61462.766 | L14: 2015 | M14: 312 | N14: 90 | O14: 140
B15: Aug | C15: =C14*103.5% -> 63613.963
B16: Sep | C16: =C15*103.5% -> 65840.452
B17: Oct | C17: =C16*103.5% -> 68144.868
B18: Nov | C18: =C17*103.5% -> 70529.938
B19: Dec | C19: =C18*103.5% -> 72998.486
B20: Total | C20: =SUBTOTAL(109,Table17[Ventas proyectadas]) -> 730098.08
A25: Año | B25: Costo de almacenamiento aproximado por terabyte
A26: 1992 | B26: 1000000
A27: 1993 | B27: 550000
A28: 1994 | B28: 303000
A29: 1995 | B29: 170000
A30: 1996 | B30: 92000
A31: 1997 | B31: 50200
A32: 1998 | B32: 27500
A33: 1999 | B33: 15500
A34: 2000 | B34: 8000
A35: 2001 | B35: 4500
A36: 2002 | B36: 2600
A37: 2003 | B37: 1400
... A49: 2015 | B49: 1
B61: Miles
A62: Mercury | B62: 36000000
A63: Venus | B63: 67000000
A64: Earth | B64: 92960000
A65: Mars | B65: 141700000
A66: Jupiter | B66: 483500000
A67: Saturn | B67: 888750000
A68: Uranus | B68: 1783744300
A69: Neptune | B69: 2797770000
A84: 89.325
A85: 93.483
A86: 95.119
...

Sheet H28
B7: Minigráficos de línea
B9: Número de fondo | C9: Ene | D9: Feb | E9: Mar | F9: Abr | G9: May | H9: Jun | I9: Sparklines
B10: A-13 | C10: 103.98 | D10: 98.92 | E10: 88.12 | F10: 86.34 | G10: 75.58 | H10: 71.2
B11: C-09 | C11: 212.74 | D11: 218.7 | E11: 202.18 | F11: 198.56 | G11: 190.12 | H11: 181.74
B12: K-88 | C12: 75.74 | D12: 73.68 | E12: 69.86 | F12: 60.34 | G12: 64.92 | H12: 59.46
B13: W-91 | C13: 91.78 | D13: 95.44 | E13: 98.1 | F13: 99.46 | G13: 98.68 | H13: 105.86
B14: M-03 | C14: 324.48 | D14: 309.14 | E14: 313.1 | F14: 287.82 | G14: 276.24 | H14: 260.9
B16: Minigráficos de columna
B18: Número de fondo | C18: Ene | D18: Feb | E18: Mar | F18: Abr | G18: May | H18: Jun | I18: Sparklines
B19: A-13 | C19: 103.98 | D19: 98.92 | E19: 88.12 | F19: 86.34 | G19: 75.58 | H19: 71.2
B20: C-09 | C20: 212.74 | D20: 218.7 | E20: 202.18 | F20: 198.56 | G20: 190.12 | H20: 181.74
B21: K-88 | C21: 75.74 | D21: 73.68 | E21: 69.86 | F21: 60.34 | G21: 64.92 | H21: 59.46
B22: W-91 | C22: 91.78 | D22: 95.44 | E22: 98.1 | F22: 99.46 | G22: 98.68 | H22: 105.86
B23: M-03 | C23: 324.48 | D23: 309.14 | E23: 313.1 | F23: 287.82 | G23: 276.24 | H23: 260.9
B25: Minigráficos de ganancias/pérdidas
B27: Número de fondo | C27: Ene | D27: Feb | E27: Mar | F27: Abr | G27: May | H27: Jun | I27: Sparklines
B28: A-13 | C28: =NA() -> #N/A | D28: =D19-C19 -> -5.06 | E28: =E19-D19 -> -10.8 | F28: =F19-E19 -> -1.78 | G28: =G19-F19 -> -10.76 | H28: =H19-G19 -> -4.38
B29: C-09 | C29: =NA() -> #N/A | D29: =D20-C20 -> 5.96 | E29: =E20-D20 -> -16.52 | F29: =F20-E20 -> -3.62 | G29: =G20-F20 -> -8.44 | H29: =H20-G20 -> -8.38
B30: K-88 | C30: =NA() -> #N/A | D30: =D21-C21 -> -2.06 | E30: =E21-D21 -> -3.82 | F30: =F21-E21 -> -9.52 | G30: =G21-F21 -> 4.58 | H30: =H21-G21 -> -5.46
B31: W-91 | C31: =NA() -> #N/A | D31: =D22-C22 -> 3.66 | E31: =E22-D22 -> 2.66 | F31: =F22-E22 -> 1.36 | G31: =G22-F22 -> -0.78 | H31: =H22-G22 -> 7.18
B32: M-03 | C32: =NA() -> #N/A | D32: =D23-C23 -> -15.34 | E32: =E23-D23 -> 3.96 | F32: =F23-E23 -> -25.28 | G32: =G23-F23 -> -11.58 | H32: =H23-G23 -> -15.34

Sheet H29
B7: Precipitación mensual promedio (pulgadas)
C9: Ene | D9: Feb | E9: Mar | F9: Abr | G9: May | H9: Jun | I9: Jul | J9: Ago | K9: Sep | L9: Oct | M9: Nov | N9: Dic
B10: ASHEVILLE, NC | C10: 4.06 | D10: 3.83 | E10: 4.59 | F10: 3.5 | G10: 4.41 | H10: 4.38 | I10: 3.87 | J10: 4.3 | K10: 3.72 | L10: 3.17 | M10: 3.82 | N10: 3.39
B11: BAKERSFIELD, CA | C11: 1.18 | D11: 1.21 | E11: 1.41 | F11: 0.45 | G11: 0.24 | H11: 0.12 | I11: 0 | J11: 0.08 | K11: 0.15 | L11: 0.3 | M11: 0.59 | N11: 0.76
B12: BATON ROUGE, LA | C12: 6.19 | D12: 5.1 | E12: 5.07 | F12: 5.56 | G12: 5.34 | H12: 5.33 | I12: 5.96 | J12: 5.86 | K12: 4.84 | L12: 3.81 | M12: 4.76 | N12: 5.26
B13: BILLINGS, MT | C13: 0.81 | D13: 0.57 | E13: 1.12 | F13: 1.74 | G13: 2.48 | H13: 1.89 | I13: 1.28 | J13: 0.85 | K13: 1.34 | L13: 1.26 | M13: 0.75 | N13: 0.67
B14: DAYTONA BEACH, FL | C14: 3.13 | D14: 2.74 | E14: 3.84 | F14: 2.54 | G14: 3.26 | H14: 5.69 | I14: 5.17 | J14: 6.09 | K14: 6.61 | L14: 4.48 | M14: 3.03 | N14: 2.71
B15: EUGENE, OR | C15: 7.65 | D15: 6.35 | E15: 5.8 | F15: 3.66 | G15: 2.66 | H15: 1.53 | I15: 0.64 | J15: 0.99 | K15: 1.54 | L15: 3.35 | M15: 8.44 | N15: 8.29
B16: HONOLULU,HI | C16: 2.73 | D16: 2.35 | E16: 1.89 | F16: 1.11 | G16: 0.78 | H16: 0.43 | I16: 0.5 | J16: 0.46 | K16: 0.74 | L16: 2.18 | M16: 2.26 | N16: 2.85
B17: ST. LOUIS, MO | C17: 2.14 | D17: 2.28 | E17: 3.6 | F17: 3.69 | G17: 4.11 | H17: 3.76 | I17: 3.9 | J17: 2.98 | K17: 2.96 | L17: 2.76 | M17: 3.71 | N17: 2.86
B18: TUCSON, AZ | C18: 0.99 | D18: 0.88 | E18: 0.81 | F18: 0.28 | G18: 0.24 | H18: 0.24 | I18: 2.07 | J18: 2.3 | K18: 1.45 | L18: 1.21 | M18: 0.67 | N18: 1.03

Sheet H30
B7: 14 | C7: 25 | D7: 15 | E7: 12 | F7: 7 | G7: -6 | H7: -9 | I7: -3 | J7: 2 | K7: 6 | L7: 8

Sheet H31
B7: 12 | C7: 9 | D7: -6 | E7: -12 | F7: 2 | G7: 8 | H7: 16 | I7: 14 | K7: Default
B8: 12 | C8: 9 | D8: -6 | E8: -12 | F8: 2 | G8: 8 | H8: 16 | I8: 14 | K8: Markers
B9: 12 | C9: 9 | D9: -6 | E9: -12 | F9: 2 | G9: 8 | H9: 16 | I9: 14 | K9: High Point, Low Point
B10: 12 | C10: 9 | D10: -6 | E10: -12 | F10: 2 | G10: 8 | H10: 16 | I10: 14 | K10: First Point, Last Point
B11: 12 | C11: 9 | D11: -6 | E11: -12 | F11: 2 | G11: 8 | H11: 16 | I11: 14 | K11: Negative Points

Sheet H32
B7: Cada minigráfico tiene su propia escala
C8: Ene | D8: Feb | E8: Mar | F8: Abr | G8: May | H8: Jun | I8: Sparklines
B9: Product A | C9: 100 | D9: =C9+RANDBETWEEN(-5,15) -> 107 | E9: =D9+RANDBETWEEN(-5,15) -> 122 | F9: =E9+RANDBETWEEN(-5,15) -> 118 | G9: =F9+RANDBETWEEN(-5,15) -> 128 | H9: =G9+RANDBETWEEN(-5,15) -> 132
B10: Product B | C10: 300 | D10: =C10+RANDBETWEEN(-5,15) -> 300 | E10: =D10+RANDBETWEEN(-5,15) -> 296 | F10: =E10+RANDBETWEEN(-5,15) -> 307 | G10: =F10+RANDBETWEEN(-5,15) -> 321 | H10: =G10+RANDBETWEEN(-5,15) -> 319
B11: Product C | C11: 600 | D11: =C11+RANDBETWEEN(-5,15) -> 606 | E11: =D11+RANDBETWEEN(-5,15) -> 614 | F11: =E11+RANDBETWEEN(-5,15) -> 617 | G11: =F11+RANDBETWEEN(-5,15) -> 613 | H11: =G11+RANDBETWEEN(-5,15) -> 628
B14: Todos los minigráficos usan la misma escala
C15: Ene | D15: Feb | E15: Mar | F15: Abr | G15: May | H15: Jun | I15: Sparklines
B16: Product A | C16: =C9 -> 100 | D16: =D9 -> 107 | E16: =E9 -> 122 | F16: =F9 -> 118 | G16: =G9 -> 128 | H16: =H9 -> 132
B17: Product B | C17: =C10 -> 300 | D17: =D10 -> 300 | E17: =E10 -> 296 | F17: =F10 -> 307 | G17: =G10 -> 321 | H17: =H10 -> 319
B18: Product C | C18: =C11 -> 600 | D18: =D11 -> 606 | E18: =E11 -> 614 | F18: =F11 -> 617 | G18: =G11 -> 613 | H18: =H11 -> 628

Sheet H33
B7: Páginas leídas
B8: Meta Mensual: | D8: 500
C10: Páginas leídas
C11: Ene | D11: Feb | E11: Mar | F11: Abr | G11: May | H11: Jun
B12: Ann | C12: 450 | D12: 412 | E12: 632 | F12: 663 | G12: 702 | H12: 512
B13: Bob | C13: 309 | D13: 215 | E13: 194 | F13: 189 | G13: 678 | H13: 256
B14: Chuck | C14: 608 | D14: 783 | E14: 765 | F14: 832 | G14: 483 | H14: 763
B15: Dave | C15: 409 | D15: 415 | E15: 522 | F15: 598 | G15: 421 | H15: 433
B16: Ellen | C16: 790 | D16: 893 | E16: 577 | F16: 802 | G16: 874 | H16: 763
B17: Frank | C17: 211 | D17: 59 | E17: 0 | F17: 0 | G17: 185 | H17: 230
B18: Giselle | C18: 785 | D18: 764 | E18: 701 | F18: 784 | G18: 214 | H18: 185
B19: Henry | C19: 350 | D19: 367 | E19: 560 | F19: 583 | G19: 784 | H19: 663
C22: Páginas leídas (cumplieron o no el objetivo)
C23: Ene | D23: Feb | E23: Mar | F23: Abr | G23: May | H23: Jun
B24: Ann | C24: =IF(C12>$D$8,1,-1) -> -1 | D24: =IF(D12>$D$8,1,-1) -> -1 | E24: =IF(E12>$D$8,1,-1) -> 1 | F24: =IF(F12>$D$8,1,-1) -> 1 | G24: =IF(G12>$D$8,1,-1) -> 1 | H24: =IF(H12>$D$8,1,-1) -> 1
B25: Bob | C25: =IF(C13>$D$8,1,-1) -> -1 | D25: =IF(D13>$D$8,1,-1) -> -1 | E25: =IF(E13>$D$8,1,-1) -> -1 | F25: =IF(F13>$D$8,1,-1) -> -1 | G25: =IF(G13>$D$8,1,-1) -> 1 | H25: =IF(H13>$D$8,1,-1) -> -1
B26: Chuck | C26: =IF(C14>$D$8,1,-1) -> 1 | D26: =IF(D14>$D$8,1,-1) -> 1 | E26: =IF(E14>$D$8,1,-1) -> 1 | F26: =IF(F14>$D$8,1,-1) -> 1 | G26: =IF(G14>$D$8,1,-1) -> -1 | H26: =IF(H14>$D$8,1,-1) -> 1
B27: Dave | C27: =IF(C15>$D$8,1,-1) -> -1 | D27: =IF(D15>$D$8,1,-1) -> -1 | E27: =IF(E15>$D$8,1,-1) -> 1 | F27: =IF(F15>$D$8,1,-1) -> 1 | G27: =IF(G15>$D$8,1,-1) -> -1 | H27: =IF(H15>$D$8,1,-1) -> -1
B28: Ellen | C28: =IF(C16>$D$8,1,-1) -> 1 | D28: =IF(D16>$D$8,1,-1) -> 1 | E28: =IF(E16>$D$8,1,-1) -> 1 | F28: =IF(F16>$D$8,1,-1) -> 1 | G28: =IF(G16>$D$8,1,-1) -> 1 | H28: =IF(H16>$D$8,1,-1) -> 1
B29: Frank | C29: =IF(C17>$D$8,1,-1) -> -1 | D29: =IF(D17>$D$8,1,-1) -> -1 | E29: =IF(E17>$D$8,1,-1) -> -1 | F29: =IF(F17>$D$8,1,-1) -> -1 | G29: =IF(G17>$D$8,1,-1) -> -1 | H29: =IF(H17>$D$8,1,-1) -> -1
B30: Giselle | C30: =IF(C18>$D$8,1,-1) -> 1 | D30: =IF(D18>$D$8,1,-1) -> 1 | E30: =IF(E18>$D$8,1,-1) -> 1 | F30: =IF(F18>$D$8,1,-1) -> 1 | G30: =IF(G18>$D$8,1,-1) -> -1 | H30: =IF(H18>$D$8,1,-1) -> -1
B31: Henry | C31: =IF(C19>$D$8,1,-1) -> -1 | D31: =IF(D19>$D$8,1,-1) -> -1 | E31: =IF(E19>$D$8,1,-1) -> 1 | F31: =IF(F19>$D$8,1,-1) -> 1 | G31: =IF(G19>$D$8,1,-1) -> 1 | H31: =IF(H19>$D$8,1,-1) -> 1
C35: Páginas leídas (en relación con el objetivo)
C36: Ene | D36: Feb | E36: Mar | F36: Abr | G36: May | H36: Jun
B37: =B12 -> Ann | C37: =C12-$D$8 -> -50 | D37: =D12-$D$8 -> -88 | E37: =E12-$D$8 -> 132 | F37: =F12-$D$8 -> 163 | G37: =G12-$D$8 -> 202 | H37: =H12-$D$8 -> 12
B38: =B13 -> Bob | C38: =C13-$D$8 -> -191 | D38: =D13-$D$8 -> -285 | E38: =E13-$D$8 -> -306 | F38: =F13-$D$8 -> -311 | G38: =G13-$D$8 -> 178 | H38: =H13-$D$8 -> -244
B39: =B14 -> Chuck | C39: =C14-$D$8 -> 108 | D39: =D14-$D$8 -> 283 | E39: =E14-$D$8 -> 265 | F39: =F14-$D$8 -> 332 | G39: =G14-$D$8 -> -17 | H39: =H14-$D$8 -> 263
B40: =B15 -> Dave | C40: =C15-$D$8 -> -91 | D40: =D15-$D$8 -> -85 | E40: =E15-$D$8 -> 22 | F40: =F15-$D$8 -> 98 | G40: =G15-$D$8 -> -79 | H40: =H15-$D$8 -> -67
B41: =B16 -> Ellen | C41: =C16-$D$8 -> 290 | D41: =D16-$D$8 -> 393 | E41: =E16-$D$8 -> 77 | F41: =F16-$D$8 -> 302 | G41: =G16-$D$8 -> 374 | H41: =H16-$D$8 -> 263
B42: =B17 -> Frank | C42: =C17-$D$8 -> -289 | D42: =D17-$D$8 -> -441 | E42: =E17-$D$8 -> -500 | F42: =F17-$D$8 -> -500 | G42: =G17-$D$8 -> -315 | H42: =H17-$D$8 -> -270
B43: =B18 -> Giselle | C43: =C18-$D$8 -> 285 | D43: =D18-$D$8 -> 264 | E43: =E18-$D$8 -> 201 | F43: =F18-$D$8 -> 284 | G43: =G18-$D$8 -> -286 | H43: =H18-$D$8 -> -315
B44: =B19 -> Henry | C44: =C19-$D$8 -> -150 | D44: =D19-$D$8 -> -133 | E44: =E19-$D$8 -> 60 | F44: =F19-$D$8 -> 83 | G44: =G19-$D$8 -> 284 | H44: =H19-$D$8 -> 163

Sheet H34
B7: Fecha | C7: Cantidad
B8: 43466 | C8: 154
B9: 43467 | C9: 201
B10: 43468 | C10: 245 | G10: <-- debe ser el tipo de eje de fecha
B11: 43469 | C11: 176
B12: 43476 | C12: 267
B13: 43477 | C13: 289
B14: 43478 | C14: 331 | G14: <-- tipo de eje de fecha
B15: 43479 | C15: 365
B16: 43483 | C16: 298
B17: 43484 | C17: 424

Sheet H35
B7: Mes | C7: Tasa
B8: Ene | C8: 0.1
B9: Feb | C9: 0.0502
B10: Mar | C10: 0.0497
B11: Abr | C11: 0.0499
B12: May | C12: 0.0489
B13: Jun | C13: 0.0472
B14: Jul | C14: 0.0468
B15: Ago | C15: 0.0456

Sheet H36
B7: Día | C7: Ventas
B8: 1 | C8: 695
B9: =B8+1 -> 2 | C9: 687
B10: =B9+1 -> 3 | C10: 687 | E10: Tendencia de 7 días:
B11: =B10+1 -> 4 | C11: 695
B12: =B11+1 -> 5 | C12: 708
B13: =B12+1 -> 6 | C13: 719
B14: =B13+1 -> 7 | C14: 726
B15: =B14+1 -> 8 | C15: 727
B16: =B15+1 -> 9 | C16: 735
B17: =B16+1 -> 10 | C17: 744
B18: =B17+1 -> 11 | C18: 744
B19: =B18+1 -> 12 | C19: 740
B20: =B19+1 -> 13 | C20: 740
B21: =B20+1 -> 14 | C21: 735
B22: =B21+1 -> 15 | C22: 750
... B26: =B25+1 -> 19 | C26: 1000
B27: =B26+1 -> 20
B28: =B27+1 -> 21
B29: =B28+1 -> 22
B30: =B29+1 -> 23
B31: =B30+1 -> 24
B32: =B31+1 -> 25
B33: =B32+1 -> 26
B34: =B33+1 -> 27
B35: =B34+1 -> 28
B36: =B35+1 -> 29
B37: =B36+1 -> 30
B38: =B37+1 -> 31
... B50: =B49+1 -> 43

Sheet H37
C7: Formatear números grandes
D8: Enero | E8: Febrero | F8: Marzo
C9: Norte | D9: 117943.61 | E9: 380439.22 | F9: 462846.08 | G9: =SUM(D9:F9) -> 961228.9 | I9: Ctrl+1
C10: Noreste | D10: 24304.534 | E10: 802648.43 | F10: 327504.54 | G10: =SUM(D10:F10) -> 1154457.5
C11: Este | D11: 313415.7 | E11: 779825.61 | F11: 904132.34 | G11: =SUM(D11:F11) -> 1997373.6
C12: Sureste | D12: 397459.21 | E12: 466308.9 | F12: 831589.08 | G12: =SUM(D12:F12) -> 1695357.2
C13: Sureste | D13: 839626.36 | E13: 117786.14 | F13: 800466.21 | G13: =SUM(D13:F13) -> 1757878.7
C14: Suroeste | D14: 622572.23 | E14: 976698.81 | F14: 807868.29 | G14: =SUM(D14:F14) -> 2407139.3
C15: Oeste | D15: 474499.15 | E15: 78914.155 | F15: 876094.8 | G15: =SUM(D15:F15) -> 1429508.1
C16: Noroeste | D16: 840582.68 | E16: 101804.6 | F16: 615611.24 | G16: =SUM(D16:F16) -> 1557998.5
C17: Totales | D17: =SUM(D9:D16) -> 3630403.5 | E17: =SUM(E9:E16) -> 3704425.9 | F17: =SUM(F9:F16) -> 5626112.6 | G17: =SUM(D17:F17) -> 12960942
C22: Comprender el formato positivo y negativo
C23: -1890
C24: -525
C25: 1982
C26: 2744
C27: 526
C28: 7419
C33: Mejor formato para porcentajes
B34: Norte | C34: 0.47
B35: Sur | C35: 0.5
B36: Este | C36: -0.23
B37: Oeste | C37: -0.43
C42: Suprimir ceros
D43: Jim | E43: Tim | F43: Kim
C44: Impresoras | D44: 37000 | E44: 64000 | F44: 24000
C45: Copiadoras | D45: 18000 | E45: 29000 | F45: 58000
C46: Scanners | D46: 0 | E46: 77000 | F46: 88000
C47: Contratos de servicio | D47: 16000 | E47: 12000 | F47: 0
C48: Garantías | D48: 65000 | E48: 88000 | F48: 16000
C56: Formato de fechas y horas
C57: 43466
C58: 43497
C59: 43525
C60: 43556
C61: 43496.819
C62: 43496.821

Sheet H38
B7: Símbolos | C7: ▲▼
B9: vs. Mes anterior | C9: Mercado | D9: Mes actual
B10: 0.032 | C10: Grandes Lagos | D10: 72505
B11: 0.3 | C11: Nueva Inglaterra | D11: 283324
B12: -0.057 | C12: Nueva York Norte | D12: 148790
B13: 0.267 | C13: Sur de nueva york | D13: 68009
B14: -0.022 | C14: Ohio | D14: 98308
B15: 0.336 | C15: Valle de Shenandoah | D15: 200076

Sheet H39
AF1: z
AC26: Norte | AD26: Sur | AE26: Este | AF26: Oeste
AC27: 0.35 | AD27: 0.23 | AE27: 0.44 | AF27: 0.22
AB28: Producto A | AC28: 539.47711 | AD28: 399.64081 | AE28: 430.24117 | AF28: 396.76659
AB29: Producto B | AC29: 261.63052 | AD29: 433.77434 | AE29: 399.72889 | AF29: 758.57835
AB30: Producto C | AC30: 451.79119 | AD30: 616.08228 | AE30: 697 | AF30: 399.72889
AB31: Producto D | AC31: 925.27158 | AD31: 806.94019 | AE31: 523.07283 | AF31: 523.07283

Sheet H40
C7: Editar datos
B8: Porcentaje de ingresos | C8: 0.35
B9: Unidades hasta la fecha | C9: 2178
B10: Margen hasta la fecha | C10: 0.22

Sheet H41
B8: Metric 1
B9: 0.5
C11: 0.91 | D11: 0.92 | E11: 0.93 | F11: 0.94 | G11: 0.95 | H11: 0.96 | I11: 0.97 | J11: 0.98 | K11: 0.99 | L11: 1
C12: 0.81 | D12: 0.82 | E12: 0.83 | F12: 0.84 | G12: 0.85 | H12: 0.86 | I12: 0.87 | J12: 0.88 | K12: 0.89 | L12: 0.9
C13: 0.71 | D13: 0.72 | E13: 0.73 | F13: 0.74 | G13: 0.75 | H13: 0.76 | I13: 0.77 | J13: 0.78 | K13: 0.79 | L13: 0.8
C14: 0.61 | D14: 0.62 | E14: 0.63 | F14: 0.64 | G14: 0.65 | H14: 0.66 | I14: 0.67 | J14: 0.68 | K14: 0.69 | L14: 0.7
C15: 0.51 | D15: 0.52 | E15: 0.53 | F15: 0.54 | G15: 0.55 | H15: 0.56 | I15: 0.57 | J15: 0.58 | K15: 0.59 | L15: 0.6
C16: 0.41 | D16: 0.42 | E16: 0.43 | F16: 0.44 | G16: 0.45 | H16: 0.46 | I16: 0.47 | J16: 0.48 | K16: 0.49 | L16: 0.5
C17: 0.31 | D17: 0.32 | E17: 0.33 | F17: 0.34 | G17: 0.35 | H17: 0.36 | I17: 0.37 | J17: 0.38 | K17: 0.39 | L17: 0.4
C18: 0.21 | D18: 0.22 | E18: 0.23 | F18: 0.24 | G18: 0.25 | H18: 0.26 | I18: 0.27 | J18: 0.28 | K18: 0.29 | L18: 0.3
C19: 0.11 | D19: 0.12 | E19: 0.13 | F19: 0.14 | G19: 0.15 | H19: 0.16 | I19: 0.17 | J19: 0.18 | K19: 0.19 | L19: 0.2
C20: 0.01 | D20: 0.02 | E20: 0.03 | F20: 0.04 | G20: 0.05 | H20: 0.06 | I20: 0.07 | J20: 0.08 | K20: 0.09 | L20: 0.1
B22: Metric 2
B23: 0.44
C25: 0.91 | D25: 0.92 | E25: 0.93 | F25: 0.94 | G25: 0.95 | H25: 0.96 | I25: 0.97 | J25: 0.98 | K25: 0.99 | L25: 1
C26: 0.81 | D26: 0.82 | E26: 0.83 | F26: 0.84 | G26: 0.85 | H26: 0.86 | I26: 0.87 | J26: 0.88 | K26: 0.89 | L26: 0.9
C27: 0.71 | D27: 0.72 | E27: 0.73 | F27: 0.74 | G27: 0.75 | H27: 0.76 | I27: 0.77 | J27: 0.78 | K27: 0.79 | L27: 0.8
C28: 0.61 | D28: 0.62 | E28: 0.63 | F28: 0.64 | G28: 0.65 | H28: 0.66 | I28: 0.67 | J28: 0.68 | K28: 0.69 | L28: 0.7
C29: 0.51 | D29: 0.52 | E29: 0.53 | F29: 0.54 | G29: 0.55 | H29: 0.56 | I29: 0.57 | J29: 0.58 | K29: 0.59 | L29: 0.6
C30: 0.41 | D30: 0.42 | E30: 0.43 | F30: 0.44 | G30: 0.45 | H30: 0.46 | I30: 0.47 | J30: 0.48 | K30: 0.49 | L30: 0.5
C31: 0.31 | D31: 0.32 | E31: 0.33 | F31: 0.34 | G31: 0.35 | H31: 0.36 | I31: 0.37 | J31: 0.38 | K31: 0.39 | L31: 0.4
C32: 0.21 | D32: 0.22 | E32: 0.23 | F32: 0.24 | G32: 0.25 | H32: 0.26 | I32: 0.27 | J32: 0.28 | K32: 0.29 | L32: 0.3
C33: 0.11 | D33: 0.12 | E33: 0.13 | F33: 0.14 | G33: 0.15 | H33: 0.16 | I33: 0.17 | J33: 0.18 | K33: 0.19 | L33: 0.2
C34: 0.01 | D34: 0.02 | E34: 0.03 | F34: 0.04 | G34: 0.05 | H34: 0.06 | I34: 0.07 | J34: 0.08 | K34: 0.09 | L34: 0.1
B38: Metric 3
B39: 0.79
C41: 0.91 | D41: 0.92 | E41: 0.93 | F41: 0.94 | G41: 0.95 | H41: 0.96 | I41: 0.97 | J41: 0.98 | K41: 0.99 | L41: 1
C42: 0.81 | D42: 0.82 | E42: 0.83 | F42: 0.84 | G42: 0.85 | H42: 0.86 | I42: 0.87 | J42: 0.88 | K42: 0.89 | L42: 0.9
C43: 0.71 | D43: 0.72 | E43: 0.73 | F43: 0.74 | G43: 0.75 | H43: 0.76 | I43: 0.77 | J43: 0.78 | K43: 0.79 | L43: 0.8
C44: 0.61 | D44: 0.62 | E44: 0.63 | F44: 0.64 | G44: 0.65 | H44: 0.66 | I44: 0.67 | J44: 0.68 | K44: 0.69 | L44: 0.7
C45: 0.51 | D45: 0.52 | E45: 0.53 | F45: 0.54 | G45: 0.55 | H45: 0.56 | I45: 0.57 | J45: 0.58 | K45: 0.59 | L45: 0.6
C46: 0.41 | D46: 0.42 | E46: 0.43 | F46: 0.44 | G46: 0.45 | H46: 0.46 | I46: 0.47 | J46: 0.48 | K46: 0.49 | L46: 0.5
C47: 0.31 | D47: 0.32 | E47: 0.33 | F47: 0.34 | G47: 0.35 | H47: 0.36 | I47: 0.37 | J47: 0.38 | K47: 0.39 | L47: 0.4
C48: 0.21 | D48: 0.22 | E48: 0.23 | F48: 0.24 | G48: 0.25 | H48: 0.26 | I48: 0.27 | J48: 0.28 | K48: 0.29 | L48: 0.3
C49: 0.11 | D49: 0.12 | E49: 0.13 | F49: 0.14 | G49: 0.15 | H49: 0.16 | I49: 0.17 | J49: 0.18 | K49: 0.19 | L49: 0.2
C50: 0.01 | D50: 0.02 | E50: 0.03 | F50: 0.04 | G50: 0.05 | H50: 0.06 | I50: 0.07 | J50: 0.08 | K50: 0.09 | L50: 0.1
