Workbook
Name CustomerCity: 'M4_Rangos y Tablas'!$N$20:$N$120
Name CustomerCountry: 'M4_Rangos y Tablas'!$P$20:$P$120
Name CustomerName: 'M4_Rangos y Tablas'!$M$20:$M$120
Name CustomerState: 'M4_Rangos y Tablas'!$O$20:$O$120
Name DeliveryDueDate: 'M4_Rangos y Tablas'!$K$20:$K$120
Name EmployeeID: Table1[EmployeeID]
Name ItemCost: 'M4_Rangos y Tablas'!$H$20:$H$120
Name ItemPrice: 'M4_Rangos y Tablas'!$I$20:$I$120
Name Model: 'M4_Rangos y Tablas'!$U$20:$U$120
Name OrderDate: 'M4_Rangos y Tablas'!$J$20:$J$120
Name OrderNo: 'M4_Rangos y Tablas'!$E$20:$E$120
Name OrderQuantity: 'M4_Rangos y Tablas'!$G$20:$G$120
Name OrderToDelivery: 'M4_Rangos y Tablas'!$L$20:$L$120
Name Product: 'M4_Rangos y Tablas'!$S$20:$S$120
Name ProductCategory: 'M4_Rangos y Tablas'!$Q$20:$Q$120
Name ProductColor: 'M4_Rangos y Tablas'!$T$20:$T$120
Name ProductSubcategory: 'M4_Rangos y Tablas'!$R$20:$R$120
Name SalesOrderLineKey: 'M4_Rangos y Tablas'!$F$20:$F$120

Sheet M1_Introducción
B2: Introducción a Excel
B3: Este módulo es una visión introductoria a Excel, donde comprenderás para qué es utilizado Excel, elementos de un libro de trabajo, desplazamiento dentro de las hojas, introducción a
B4: la cinta de opciones, atajos del teclado, cuadros de diálogo, paneles de tareas y más.
B6: Tema | C6: Check | F6: Libros y Hojas
B7: Libros y Hojas | C7: X
B8: Desplazamiento en Hojas | C8: x | F8: Nombre Inglés | G8: Nombre Español
B9: Cinta de Opciones | C9: X | F9: Collapse Ribbon buttom | G9: Botón Colapsar la Cinta
B10: Menús contextuales | C10: X | F10: Column letters | G10: Letras de columna
B11: Barra de acceso rápido | C11: x | F11: File button | G11: Botón de Archivo
B12: Cuadros de diálogo | C12: X | F12: Formula bar | G12: Barra de fórmulas
F13: Horizontal scrollbar | G13: Barra de desplazamiento horizontal
F14: Macro recorder indicator | G14: Indicador de grabadora de macros
F15: Name box | G15: Cuadro de nombre
F16: New sheet button | G16: Botón de Nueva hoja
F17: Page view buttons | G17: Botones de vista de página
F18: Quick Access toolbar | G18: Barra de herramientas de acceso rápido
F19: Cinta de opciones | G19: Cinta
F20: Ribbon Display Options | G20: Opciones de visualización de la Cinta
F21: Row numbers | G21: Números de fila
F22: Search | G22: Control de búsqueda
F23: Selected cell indicator | G23: Indicador de celda seleccionada
F24: Sheet tabs | G24: Pestañas de hoja
... F31: Zoom control | G31: Control de zoom

Sheet M2_Ingresar y Editar Datos
B2: Ingresar y Editar Datos
B3: Este módulo describe lo que necesitas saber sobre cómo ingresar y modificar datos en tus hojas de cálculo. Como verás, Excel no trata todos los datos de la misma manera.
B4: Por lo tanto, necesitas aprender sobre los diferentes tipos de datos que puedes usar en una hoja de cálculo de Excel.
B6: Tema | C6: Check | E6: Sin Formato | F6: Con Formato | G6: Tipo | I6: Combinación de Teclas | J6: Formato Aplicado
B7: Explorar tipos de datos | C7: x | E7: 1200 | F7: 1200 | G7: Currency | I7: Ctrl+Shift+1 | J7: Formato de número general (valores sin formato)
B8: Ingresar texto y valores | C8: x | E8: 0.231 | F8: 0.231 | G8: Percentage | I8: Ctrl+Shift+$ | J8: Formato de moneda con dos decimales (números negativos en rojo y entre paréntesis)
B9: Ingresar fechas y horas | C9: x | E9: 43603 | F9: =E9 -> 43603 | G9: Short Date | I9: Ctrl+Shift+% | J9: Formato de porcentaje sin decimales
B10: Modificar contenido de celdas | C10: x | E10: 43603 | F10: =E10 -> 43603 | G10: Long Date | I10: Ctrl+Shift+# | J10: Formato de fecha con día, mes y año* (sólo funciona en algunos teclados)
B11: Aplicar formato numérico | C11: x | E11: 123439832 | F11: 123439832 | G11: Accounting
E12: 5559832 | F12: 5559832 | G12: Phone Number
E13: 434988723 | F13: 434988723 | G13: Social Security Number
E14: 0.552 | F14: 0.552 | G14: Time
E15: 0.25 | F15: 0.25 | G15: Fraction
E16: 12332354090 | F16: 12332354090 | G16: Scientific

Sheet M3_Operaciones Básicas de Hojas
B2: Operaciones Básicas de Hojas
B3: Este módulo cubre información básica sobre libros de trabajo, hojas de cálculo y ventanas.
B4: Descubrirás consejos y técnicas para ayudarte a tomar el control de tus hojas de cálculo y trabajar de manera más eficiente.
B6: Tema | C6: Check | E6: OrderNo | F6: SalesOrderLineKey | G6: OrderQuantity | H6: ItemCost | I6: ItemPrice | J6: OrderDate | K6: DeliveryDueDate | L6: OrderToDelivery | M6: CustomerName | N6: CustomerCity | O6: CustomerState | P6: CustomerCountry | Q6: ProductCategory | R6: ProductSubcategory | S6: Product | T6: ProductColor | U6: Model
B7: Fundamentos de Hojas | C7: x | E7: SO43697 | F7: 43697001 | G7: 1 | H7: 2171.29 | I7: 3578.27 | J7: 42917 | K7: 42921 | L7: 4 | M7: Cole Watson | N7: Metchosin | O7: British Columbia | P7: Canada | Q7: Bikes | R7: Road Bikes | S7: Road-150 Red, 62 | T7: Red | U7: Road-150
B8: Controlar Vista de Hoja | C8: x | E8: SO43698 | F8: 43698001 | G8: 1 | H8: 1912.15 | I8: 3399.99 | J8: 42917 | K8: 42927 | L8: 10 | M8: Rachael Martinez | N8: Pantin | O8: Seine Saint Denis | P8: France | Q8: Bikes | R8: Mountain Bikes | S8: Mountain-100 Silver, 44 | T8: Silver | U8: Mountain-100
B9: Trabajar con Filas y Columnas | C9: x | E9: SO43699 | F9: 43699001 | G9: 1 | H9: 1912.15 | I9: 3399.99 | J9: 42917 | K9: 42922 | L9: 5 | M9: Sydney Wright | N9: Lebanon | O9: Oregon | P9: United States | Q9: Bikes | R9: Mountain Bikes | S9: Mountain-100 Silver, 44 | T9: Silver | U9: Mountain-100
E10: SO43700 | F10: 43700001 | G10: 1 | H10: 413.15 | I10: 699.1 | J10: 42917 | K10: 42926 | L10: 9 | M10: Ruben Prasad | N10: Beverly Hills | O10: California | P10: United States | Q10: Bikes | R10: Road Bikes | S10: Road-650 Black, 62 | T10: Black | U10: Road-650
E11: SO43701 | F11: 43701001 | G11: 1 | H11: 1912.15 | I11: 3399.99 | J11: 42917 | K11: 42927 | L11: 10 | M11: Christy Zhu | N11: North Ryde | O11: New South Wales | P11: Australia | Q11: Bikes | R11: Mountain Bikes | S11: Mountain-100 Silver, 44 | T11: Silver | U11: Mountain-100
E12: SO43702 | F12: 43702001 | G12: 1 | H12: 2171.29 | I12: 3578.27 | J12: 42917 | K12: 42921 | L12: 4 | M12: Colin Anand | O12: California | P12: United States | Q12: Bikes | R12: Road Bikes | S12: Road-150 Red, 44 | T12: Red | U12: Road-150
E13: SO43703 | F13: 43703001 | G13: 1 | H13: 2171.29 | I13: 3578.27 | J13: 42917 | K13: 42923 | L13: 6 | M13: Albert Alvarez | N13: Perth | O13: South Australia | P13: Australia | Q13: Bikes | R13: Road Bikes | S13: Road-150 Red, 62 | T13: Red | U13: Road-150
E14: SO43704 | F14: 43704001 | G14: 1 | H14: 1898.09 | I14: 3374.99 | J14: 42917 | K14: 42920 | L14: 3 | M14: Julio Ruiz | N14: East Brisbane | O14: Queensland | P14: Australia | Q14: Bikes | R14: Mountain Bikes | S14: Mountain-100 Black, 48 | T14: Black | U14: Mountain-100
E15: SO43705 | F15: 43705001 | G15: 1 | H15: 1912.15 | I15: 3399.99 | J15: 42917 | K15: 42921 | L15: 4 | M15: Curtis Lu | N15: East Brisbane | O15: Queensland | P15: Australia | Q15: Bikes | R15: Mountain Bikes | S15: Mountain-100 Silver, 38 | T15: Silver | U15: Mountain-100
E16: SO43706 | F16: 43706001 | G16: 1 | H16: 2171.29 | I16: 3578.27 | J16: 42918 | K16: 42924 | L16: 6 | M16: Edward Brown | N16: Santa Monica | O16: California | P16: United States | Q16: Bikes | R16: Road Bikes | S16: Road-150 Red, 48 | T16: Red | U16: Road-150
E17: SO43707 | F17: 43707001 | G17: 1 | H17: 2171.29 | I17: 3578.27 | J17: 42918 | K17: 42925 | L17: 7 | M17: Emma Brown | N17: Lemon Grove | O17: California | P17: United States | Q17: Bikes | R17: Road Bikes | S17: Road-150 Red, 48 | T17: Red | U17: Road-150
E18: SO43708 | F18: 43708001 | G18: 1 | H18: 413.15 | I18: 699.1 | J18: 42918 | K18: 42921 | L18: 3 | M18: Brad Deng | N18: Liverpool | O18: England | P18: United Kingdom | Q18: Bikes | R18: Road Bikes | S18: Road-650 Red, 52 | T18: Red | U18: Road-650
E19: SO43709 | F19: 43709001 | G19: 1 | H19: 2171.29 | I19: 3578.27 | J19: 42918 | K19: 42923 | L19: 5 | M19: Martha Xu | N19: Rockhampton | O19: Queensland | P19: Australia | Q19: Bikes | R19: Road Bikes | S19: Road-150 Red, 52 | T19: Red | U19: Road-150
E20: SO43710 | F20: 43710001 | G20: 1 | H20: 2171.29 | I20: 3578.27 | J20: 42918 | K20: 42926 | L20: 8 | M20: Katrina Raji | N20: Wollongong | O20: New South Wales | P20: Australia | Q20: Bikes | R20: Road Bikes | S20: Road-150 Red, 56 | T20: Red | U20: Road-150
E21: SO43711 | F21: 43711001 | G21: 1 | H21: 2171.29 | I21: 3578.27 | J21: 42918 | K21: 42928 | L21: 10 | M21: Courtney Edwards | N21: Milwaukie | O21: Oregon | P21: United States | Q21: Bikes | R21: Road Bikes | S21: Road-150 Red, 56 | T21: Red | U21: Road-150
E22: SO43712 | F22: 43712001 | G22: 1 | H22: 2171.29 | I22: 3578.27 | J22: 42918 | K22: 42924 | L22: 6 | M22: Abigail Henderson | N22: Werne | O22: Nordrhein-Westfalen | P22: Germany | Q22: Bikes | R22: Road Bikes | S22: Road-150 Red, 44 | T22: Red | U22: Road-150
E23: SO43713 | F23: 43713001 | G23: 1 | H23: 2171.29 | I23: 3578.27 | J23: 42919 | K23: 42925 | L23: 6 | M23: Sydney Rogers | N23: Burbank | O23: California | P23: United States | Q23: Bikes | R23: Road Bikes | S23: Road-150 Red, 62 | T23: Red | U23: Road-150
E24: SO43714 | F24: 43714001 | G24: 1 | H24: 2171.29 | I24: 3578.27 | J24: 42919 | K24: 42921 | L24: 2 | M24: Latasha Alonso | N24: York | O24: England | P24: United Kingdom | Q24: Bikes | R24: Road Bikes | S24: Road-150 Red, 44 | T24: Red | U24: Road-150
... E106: SO43796 | F106: 43796001 | G106: 1 | H106: 413.15 | I106: 699.1 | J106: 42929 | K106: 42939 | L106: 10 | M106: Jaime Gomez | N106: Metz | O106: Moselle | P106: France | Q106: Bikes | R106: Road Bikes | S106: Road-650 Black, 52 | T106: Black | U106: Road-650

Sheet M4_Rangos y Tablas
B2: Trabajando con Rangos y Tablas
B3: Este módulo te permitirá comprender la mejor manera de manipular celdas y rangos para ahorrar tiempo y esfuerzo, discutiendo una variedad de técnicas que son esenciales para los usuarios de Excel.
B6: Tema | C6: Check | E6: Tipos de rangos
B7: Entender Celdas y Rangos | C7: x | E7: C24 Un rango que consiste en una sola celda.
B8: Copiar y Mover Rangos | C8: x | E8: A1:B1 Dos celdas que ocupan una fila y dos columnas.
B9: Usar Nombres de Rangos | C9: x | E9: A1:A100 100 celdas en la columna A.
B10: Añadir Comentarios a Celdas | C10: x | E10: A1:D4 16 celdas (cuatro filas por cuatro columnas).
B11: Trabajar con Tablas | C11: x | E11: C1:C1048576 Una columna entera de celdas; este rango también se puede expresar como C:C.
E12: A6:XFD6 Una fila entera de celdas; este rango también se puede expresar como 6:6.
B13: Selección | E13: A1:XFD1048576 Todas las celdas en una hoja de cálculo. Este rango también se puede expresar como A:XFD o 1:1048576.
B14: Continua (shift)
B15: Discontinua (ctrl) | E15: EmployeeID | F15: Name | G15: Department | H15: Hire Date | I15: Salary | J15: Days Employeed
E16: 00001 | F16: John Smith | G16: Marketing | H16: 36989 | I16: 80000 | J16: =NOW()-Table1[[#This Row],[Hire Date]] -> 8321.5309
E17: 00002 | F17: Jane Burns | G17: Accounting | H17: 35411 | I17: 110000 | J17: =NOW()-Table1[[#This Row],[Hire Date]] -> 9899.5309
E18: Total | I18: =SUBTOTAL(109,Table1[Salary]) -> 190000
E20: OrderNo | F20: SalesOrderLineKey | G20: OrderQuantity | H20: ItemCost | I20: ItemPrice | J20: OrderDate | K20: DeliveryDueDate | L20: OrderToDelivery | M20: CustomerName | N20: CustomerCity | O20: CustomerState | P20: CustomerCountry | Q20: ProductCategory | R20: ProductSubcategory | S20: Product | T20: ProductColor | U20: Model
E21: SO43698 | F21: 43698001 | G21: 1 | H21: 1912.15 | I21: 3399.99 | J21: 42917 | K21: 42927 | L21: 10 | M21: Rachael Martinez | N21: Pantin | O21: Seine Saint Denis | P21: France | Q21: Bikes | R21: Mountain Bikes | S21: Mountain-100 Silver, 44 | T21: Silver | U21: Mountain-100
E22: SO43701 | F22: 43701001 | G22: 1 | H22: 1912.15 | I22: 3399.99 | J22: 42917 | K22: 42927 | L22: 10 | M22: Christy Zhu | N22: North Ryde | O22: New South Wales | P22: Australia | Q22: Bikes | R22: Mountain Bikes | S22: Mountain-100 Silver, 44 | T22: Silver | U22: Mountain-100
E23: SO43711 | F23: 43711001 | G23: 1 | H23: 2171.29 | I23: 3578.27 | J23: 42918 | K23: 42928 | L23: 10 | M23: Courtney Edwards | N23: Milwaukie | O23: Oregon | P23: United States | Q23: Bikes | R23: Road Bikes | S23: Road-150 Red, 56 | T23: Red | U23: Road-150
E24: SO43730 | F24: 43730001 | G24: 1 | H24: 1912.15 | I24: 3399.99 | J24: 42921 | K24: 42931 | L24: 10 | M24: Garrett Cooper | N24: Woodland Hills | O24: California | P24: United States | Q24: Bikes | R24: Mountain Bikes | S24: Mountain-100 Silver, 44 | T24: Silver | U24: Mountain-100
E25: SO43733 | F25: 43733001 | G25: 1 | H25: 2171.29 | I25: 3578.27 | J25: 42921 | K25: 42931 | L25: 10 | M25: Patrick Cook | N25: Port Orchard | O25: Washington | P25: United States | Q25: Bikes | R25: Road Bikes | S25: Road-150 Red, 48 | T25: Red | U25: Road-150
E26: SO43743 | F26: 43743001 | G26: 1 | H26: 1912.15 | I26: 3399.99 | J26: 42922 | K26: 42932 | L26: 10 | M26: Marco Mehta | N26: Warrnambool | O26: Victoria | P26: Australia | Q26: Bikes | R26: Mountain Bikes | S26: Mountain-100 Silver, 48 | T26: Silver | U26: Mountain-100
E27: SO43762 | F27: 43762001 | G27: 1 | H27: 2171.29 | I27: 3578.27 | J27: 42925 | K27: 42935 | L27: 10 | M27: Courtney Carter | N27: Lakewood | O27: California | P27: United States | Q27: Bikes | R27: Road Bikes | S27: Road-150 Red, 56 | T27: Red | U27: Road-150
E28: SO43768 | F28: 43768001 | G28: 1 | H28: 2171.29 | I28: 3578.27 | J28: 42926 | K28: 42936 | L28: 10 | M28: Evan Bailey | N28: Seattle | O28: Washington | P28: United States | Q28: Bikes | R28: Road Bikes | S28: Road-150 Red, 48 | T28: Red | U28: Road-150
E29: SO43776 | F29: 43776001 | G29: 1 | H29: 2171.29 | I29: 3578.27 | J29: 42926 | K29: 42936 | L29: 10 | M29: James Flores | N29: Neunkirchen | O29: Saarland | P29: Germany | Q29: Bikes | R29: Road Bikes | S29: Road-150 Red, 56 | T29: Red | U29: Road-150
E30: SO43792 | F30: 43792001 | G30: 1 | H30: 2171.29 | I30: 3578.27 | J30: 42928 | K30: 42938 | L30: 10 | M30: Andres Lal | N30: Port Macquarie | O30: New South Wales | P30: Australia | Q30: Bikes | R30: Road Bikes | S30: Road-150 Red, 48 | T30: Red | U30: Road-150
E31: SO43796 | F31: 43796001 | G31: 1 | H31: 413.15 | I31: 699.1 | J31: 42929 | K31: 42939 | L31: 10 | M31: Jaime Gomez | N31: Metz | O31: Moselle | P31: France | Q31: Bikes | R31: Road Bikes | S31: Road-650 Black, 52 | T31: Black | U31: Road-650
E32: SO43700 | F32: 43700001 | G32: 1 | H32: 413.15 | I32: 699.1 | J32: 42917 | K32: 42926 | L32: 9 | M32: Ruben Prasad | N32: Beverly Hills | O32: California | P32: United States | Q32: Bikes | R32: Road Bikes | S32: Road-650 Black, 62 | T32: Black | U32: Road-650
... E83: SO43697 | F83: 43697001 | G83: 1 | H83: 2171.29 | I83: 3578.27 | J83: 42917 | K83: 42921 | L83: 4 | M83: Cole Watson | N83: Metchosin | O83: British Columbia | P83: Canada | Q83: Bikes | R83: Road Bikes | S83: Road-150 Red, 62 | T83: Red | U83: Road-150
E84: SO43702 | F84: 43702001 | G84: 1 | H84: 2171.29 | I84: 3578.27 | J84: 42917 | K84: 42921 | L84: 4 | M84: Colin Anand | O84: California | P84: United States | Q84: Bikes | R84: Road Bikes | S84: Road-150 Red, 44 | T84: Red | U84: Road-150
E85: SO43705 | F85: 43705001 | G85: 1 | H85: 1912.15 | I85: 3399.99 | J85: 42917 | K85: 42921 | L85: 4 | M85: Curtis Lu | N85: East Brisbane | O85: Queensland | P85: Australia | Q85: Bikes | R85: Mountain Bikes | S85: Mountain-100 Silver, 38 | T85: Silver | U85: Mountain-100
E86: SO43728 | F86: 43728001 | G86: 1 | H86: 2171.29 | I86: 3578.27 | J86: 42921 | K86: 42925 | L86: 4 | M86: Alyssa Garcia | N86: Fremont | O86: California | P86: United States | Q86: Bikes | R86: Road Bikes | S86: Road-150 Red, 52 | T86: Red | U86: Road-150
E87: SO43734 | F87: 43734001 | G87: 1 | H87: 2171.29 | I87: 3578.27 | J87: 42921 | K87: 42925 | L87: 4 | M87: Richard Brooks | N87: Port Orchard | O87: Washington | P87: United States | Q87: Bikes | R87: Road Bikes | S87: Road-150 Red, 48 | T87: Red | U87: Road-150
E88: SO43745 | F88: 43745001 | G88: 1 | H88: 2171.29 | I88: 3578.27 | J88: 42923 | K88: 42927 | L88: 4 | M88: Manuel Fernandez | N88: Malabar | O88: New South Wales | P88: Australia | Q88: Bikes | R88: Road Bikes | S88: Road-150 Red, 44 | T88: Red | U88: Road-150
E89: SO43749 | F89: 43749001 | G89: 1 | H89: 2171.29 | I89: 3578.27 | J89: 42923 | K89: 42927 | L89: 4 | M89: Paige Murphy | N89: Issaquah | O89: Washington | P89: United States | Q89: Bikes | R89: Road Bikes | S89: Road-150 Red, 56 | T89: Red | U89: Road-150
E90: SO43767 | F90: 43767001 | G90: 1 | H90: 1898.09 | I90: 3374.99 | J90: 42925 | K90: 42929 | L90: 4 | M90: Eugene Huang | N90: Seaford | O90: Victoria | P90: Australia | Q90: Bikes | R90: Mountain Bikes | S90: Mountain-100 Black, 44 | T90: Black | U90: Mountain-100
E91: SO43778 | F91: 43778001 | G91: 1 | H91: 1912.15 | I91: 3399.99 | J91: 42926 | K91: 42930 | L91: 4 | M91: Clarence Rai | N91: Bendigo | O91: Victoria | P91: Australia | Q91: Bikes | R91: Mountain Bikes | S91: Mountain-100 Silver, 42 | T91: Silver | U91: Mountain-100
E92: SO43786 | F92: 43786001 | G92: 1 | H92: 2171.29 | I92: 3578.27 | J92: 42928 | K92: 42932 | L92: 4 | M92: Clinton Moreno | N92: Paris | O92: Seine (Paris) | P92: France | Q92: Bikes | R92: Road Bikes | S92: Road-150 Red, 44 | T92: Red | U92: Road-150
E93: SO43789 | F93: 43789001 | G93: 1 | H93: 1898.09 | I93: 3374.99 | J93: 42928 | K93: 42932 | L93: 4 | M93: Tristan Butler | N93: Kirkland | O93: Washington | P93: United States | Q93: Bikes | R93: Mountain Bikes | S93: Mountain-100 Black, 48 | T93: Black | U93: Mountain-100
E94: SO43704 | F94: 43704001 | G94: 1 | H94: 1898.09 | I94: 3374.99 | J94: 42917 | K94: 42920 | L94: 3 | M94: Julio Ruiz | N94: East Brisbane | O94: Queensland | P94: Australia | Q94: Bikes | R94: Mountain Bikes | S94: Mountain-100 Black, 48 | T94: Black | U94: Mountain-100
...

Sheet Totals
A1: Budget Summary
B3: Q1 | C3: Q2 | D3: Q3 | E3: Q4 | F3: Year Total
A4: Salaries | B4: =SUM(Operations:Manufacturing!B4) -> 286500 | C4: =SUM(Operations:Manufacturing!C4) -> 286500 | D4: =SUM(Operations:Manufacturing!D4) -> 286500 | E4: =SUM(Operations:Manufacturing!E4) -> 290500 | F4: =SUM(B4:E4) -> 1150000
A5: Travel | B5: =SUM(Operations:Manufacturing!B5) -> 40500 | C5: =SUM(Operations:Manufacturing!C5) -> 42525 | D5: =SUM(Operations:Manufacturing!D5) -> 44651.25 | E5: =SUM(Operations:Manufacturing!E5) -> 46883.812 | F5: =SUM(B5:E5) -> 174560.06
A6: Supplies | B6: =SUM(Operations:Manufacturing!B6) -> 59500 | C6: =SUM(Operations:Manufacturing!C6) -> 62475 | D6: =SUM(Operations:Manufacturing!D6) -> 65598.75 | E6: =SUM(Operations:Manufacturing!E6) -> 68878.688 | F6: =SUM(B6:E6) -> 256452.44
A7: Facility | B7: =SUM(Operations:Manufacturing!B7) -> 144000 | C7: =SUM(Operations:Manufacturing!C7) -> 144000 | D7: =SUM(Operations:Manufacturing!D7) -> 144000 | E7: =SUM(Operations:Manufacturing!E7) -> 144000 | F7: =SUM(B7:E7) -> 576000
A8: Total | B8: =SUM(B4:B7) -> 530500 | C8: =SUM(C4:C7) -> 535500 | D8: =SUM(D4:D7) -> 540750 | E8: =SUM(E4:E7) -> 550262.5 | F8: =SUM(F4:F7) -> 2157012.5
E15: Salaries | F15: =SUM(Operations:Manufacturing!F15) -> 0
E16: Travel | F16: =SUM(Operations:Manufacturing!F16) -> 0
E17: Supplies | F17: =SUM(Operations:Manufacturing!F17) -> 0
E18: Facility | F18: =SUM(Operations:Manufacturing!F18) -> 0
E19: Total | F19: =SUM(F15:F18) -> 0

Sheet Operations
A1: Operations
B3: Q1 | C3: Q2 | D3: Q3 | E3: Q4 | F3: Year Total
A4: Salaries | B4: 128500 | C4: 128500 | D4: 128500 | E4: 132500 | F4: =SUM(B4:E4) -> 518000
A5: Travel | B5: 18500 | C5: =B5*105% -> 19425 | D5: =C5*105% -> 20396.25 | E5: =D5*105% -> 21416.062 | F5: =SUM(B5:E5) -> 79737.312
A6: Supplies | B6: 16000 | C6: =B6*105% -> 16800 | D6: =C6*105% -> 17640 | E6: =D6*105% -> 18522 | F6: =SUM(B6:E6) -> 68962
A7: Facility | B7: 23000 | C7: 23000 | D7: 23000 | E7: 23000 | F7: =SUM(B7:E7) -> 92000
A8: Total | B8: =SUM(B4:B7) -> 186000 | C8: =SUM(C4:C7) -> 187725 | D8: =SUM(D4:D7) -> 189536.25 | E8: =SUM(E4:E7) -> 195438.06 | F8: =SUM(F4:F7) -> 758699.31

Sheet Marketing
A1: Marketing
B3: Q1 | C3: Q2 | D3: Q3 | E3: Q4 | F3: Year Total
A4: Salaries | B4: 120000 | C4: 120000 | D4: 120000 | E4: 120000 | F4: =SUM(B4:E4) -> 480000
A5: Travel | B5: 10000 | C5: =B5*105% -> 10500 | D5: =C5*105% -> 11025 | E5: =D5*105% -> 11576.25 | F5: =SUM(B5:E5) -> 43101.25
A6: Supplies | B6: 11000 | C6: =B6*105% -> 11550 | D6: =C6*105% -> 12127.5 | E6: =D6*105% -> 12733.875 | F6: =SUM(B6:E6) -> 47411.375
A7: Facility | B7: 29000 | C7: 29000 | D7: 29000 | E7: 29000 | F7: =SUM(B7:E7) -> 116000
A8: Total | B8: =SUM(B4:B7) -> 170000 | C8: =SUM(C4:C7) -> 171050 | D8: =SUM(D4:D7) -> 172152.5 | E8: =SUM(E4:E7) -> 173310.12 | F8: =SUM(F4:F7) -> 686512.62

Sheet Manufacturing
A1: Manufacturing
B3: Q1 | C3: Q2 | D3: Q3 | E3: Q4 | F3: Year Total
A4: Salaries | B4: 38000 | C4: 38000 | D4: 38000 | E4: 38000 | F4: =SUM(B4:E4) -> 152000
A5: Travel | B5: 12000 | C5: =B5*105% -> 12600 | D5: =C5*105% -> 13230 | E5: =D5*105% -> 13891.5 | F5: =SUM(B5:E5) -> 51721.5
A6: Supplies | B6: 32500 | C6: =B6*105% -> 34125 | D6: =C6*105% -> 35831.25 | E6: =D6*105% -> 37622.812 | F6: =SUM(B6:E6) -> 140079.06
A7: Facility | B7: 92000 | C7: 92000 | D7: 92000 | E7: 92000 | F7: =SUM(B7:E7) -> 368000
A8: Total | B8: =SUM(B4:B7) -> 174500 | C8: =SUM(C4:C7) -> 176725 | D8: =SUM(D4:D7) -> 179061.25 | E8: =SUM(E4:E7) -> 181514.31 | F8: =SUM(F4:F7) -> 711800.56

Sheet M5_Formateo de Hojas
B2: Dar Formato a Hojas
B3: En este módulo aprenderás que el formato adecuado puede ayudar a los usuarios a comprender el propósito de la hoja de cálculo y prevenir errores en la entrada de datos. El formato estilístico no es esencial para cada libro de trabajo
B4: que desarrolles, especialmente si es solo para tu propio uso. Por otro lado, solo toma unos momentos aplicar un formato sencillo y, una vez aplicado, el formato permanecerá en su lugar sin necesidad de más esfuerzo de tu parte.
B6: Tema | C6: Check | E6: Costos
B7: Conocer Herramientas de Formato | C7: x | E7: 100
B8: Darle Formato a Hoja | C8: X | E8: 200
B9: Usar Formatos Condicionales | C9: x | E9: 300
B10: Usar Estilos de Celda | C10: x | E10: 400
E11: 500

Sheet M6_Archivos y Plantillas
B2: Archivos y Plantillas
B3: Este módulo describe las operaciones que realizas con archivos de libros de trabajo: abrir, guardar, cerrar, y demás.
B4: Se discute cómo Excel utiliza los archivos y se proporciona una visión general de los diversos tipos de archivos.
B6: Tema | C6: Check
B7: Abrir y Guardar Libros de Trabajo | C7: x | E7: Autoguardado | F7: Funciona con la Nube
B8: Usar AutoRecuperación | C8: x | E8: Autorecuperación | F8: Funciona localmente
B9: Proteger Hoja y Libro | C9: x
B10: Trabajar con Plantillas | C10: x

Sheet M7_Impresiones
B2: Impresiones
B3: A pesar de las predicciones de la "oficina sin papel", el papel sigue siendo una excelente manera de llevar información y compartirla con otros, especialmente si no hay electricidad o Wi-Fi donde vas.
B4: Algunas de las hojas de cálculo que desarrollas con Excel terminarán siendo informes en papel, y querrás que se vean lo mejor posible. Descubrirás que imprimir desde Excel es bastante fácil y que puedes generar informes atractivos y bien formateados con un esfuerzo mínimo.
B6: Tema | C6: Check | E6: OrderNo | F6: SalesOrderLineKey | G6: OrderQuantity | H6: ItemCost | I6: ItemPrice | J6: OrderDate | K6: DeliveryDueDate | L6: OrderToDelivery | M6: CustomerName | N6: CustomerCity | O6: CustomerState | P6: CustomerCountry | Q6: ProductCategory | R6: ProductSubcategory | S6: Product | T6: ProductColor | U6: Model
B7: Impresión Básica | C7: X | E7: SO43698 | F7: 43698001 | G7: 1 | H7: 1912.15 | I7: 3399.99 | J7: 42917 | K7: 42927 | L7: 10 | M7: Rachael Martinez | N7: Pantin | O7: Seine Saint Denis | P7: France | Q7: Bikes | R7: Mountain Bikes | S7: Mountain-100 Silver, 44 | T7: Silver | U7: Mountain-100
B8: Cambiar Vista de Página | C8: X | E8: SO43701 | F8: 43701001 | G8: 1 | H8: 1912.15 | I8: 3399.99 | J8: 42917 | K8: 42927 | L8: 10 | M8: Christy Zhu | N8: North Ryde | O8: New South Wales | P8: Australia | Q8: Bikes | R8: Mountain Bikes | S8: Mountain-100 Silver, 44 | T8: Silver | U8: Mountain-100
B9: Configuraciones comunes de Hojas | C9: X | E9: SO43711 | F9: 43711001 | G9: 1 | H9: 2171.29 | I9: 3578.27 | J9: 42918 | K9: 42928 | L9: 10 | M9: Courtney Edwards | N9: Milwaukie | O9: Oregon | P9: United States | Q9: Bikes | R9: Road Bikes | S9: Road-150 Red, 56 | T9: Red | U9: Road-150
B10: Encabezados y Pies de Página | C10: x | E10: SO43730 | F10: 43730001 | G10: 1 | H10: 1912.15 | I10: 3399.99 | J10: 42921 | K10: 42931 | L10: 10 | M10: Garrett Cooper | N10: Woodland Hills | O10: California | P10: United States | Q10: Bikes | R10: Mountain Bikes | S10: Mountain-100 Silver, 44 | T10: Silver | U10: Mountain-100
E11: SO43733 | F11: 43733001 | G11: 1 | H11: 2171.29 | I11: 3578.27 | J11: 42921 | K11: 42931 | L11: 10 | M11: Patrick Cook | N11: Port Orchard | O11: Washington | P11: United States | Q11: Bikes | R11: Road Bikes | S11: Road-150 Red, 48 | T11: Red | U11: Road-150
E12: SO43743 | F12: 43743001 | G12: 1 | H12: 1912.15 | I12: 3399.99 | J12: 42922 | K12: 42932 | L12: 10 | M12: Marco Mehta | N12: Warrnambool | O12: Victoria | P12: Australia | Q12: Bikes | R12: Mountain Bikes | S12: Mountain-100 Silver, 48 | T12: Silver | U12: Mountain-100
E13: SO43762 | F13: 43762001 | G13: 1 | H13: 2171.29 | I13: 3578.27 | J13: 42925 | K13: 42935 | L13: 10 | M13: Courtney Carter | N13: Lakewood | O13: California | P13: United States | Q13: Bikes | R13: Road Bikes | S13: Road-150 Red, 56 | T13: Red | U13: Road-150
E14: SO43768 | F14: 43768001 | G14: 1 | H14: 2171.29 | I14: 3578.27 | J14: 42926 | K14: 42936 | L14: 10 | M14: Evan Bailey | N14: Seattle | O14: Washington | P14: United States | Q14: Bikes | R14: Road Bikes | S14: Road-150 Red, 48 | T14: Red | U14: Road-150
E15: SO43776 | F15: 43776001 | G15: 1 | H15: 2171.29 | I15: 3578.27 | J15: 42926 | K15: 42936 | L15: 10 | M15: James Flores | N15: Neunkirchen | O15: Saarland | P15: Germany | Q15: Bikes | R15: Road Bikes | S15: Road-150 Red, 56 | T15: Red | U15: Road-150
E16: SO43792 | F16: 43792001 | G16: 1 | H16: 2171.29 | I16: 3578.27 | J16: 42928 | K16: 42938 | L16: 10 | M16: Andres Lal | N16: Port Macquarie | O16: New South Wales | P16: Australia | Q16: Bikes | R16: Road Bikes | S16: Road-150 Red, 48 | T16: Red | U16: Road-150
E17: SO43796 | F17: 43796001 | G17: 1 | H17: 413.15 | I17: 699.1 | J17: 42929 | K17: 42939 | L17: 10 | M17: Jaime Gomez | N17: Metz | O17: Moselle | P17: France | Q17: Bikes | R17: Road Bikes | S17: Road-650 Black, 52 | T17: Black | U17: Road-650
E18: SO43700 | F18: 43700001 | G18: 1 | H18: 413.15 | I18: 699.1 | J18: 42917 | K18: 42926 | L18: 9 | M18: Ruben Prasad | N18: Beverly Hills | O18: California | P18: United States | Q18: Bikes | R18: Road Bikes | S18: Road-650 Black, 62 | T18: Black | U18: Road-650
E19: SO43722 | F19: 43722001 | G19: 1 | H19: 2171.29 | I19: 3578.27 | J19: 42920 | K19: 42929 | L19: 9 | M19: Albert Blanco | N19: Esher-Molesey | O19: England | P19: United Kingdom | Q19: Bikes | R19: Road Bikes | S19: Road-150 Red, 48 | T19: Red | U19: Road-150
E20: SO43727 | F20: 43727001 | G20: 1 | H20: 2171.29 | I20: 3578.27 | J20: 42920 | K20: 42929 | L20: 9 | M20: Logan Gonzales | N20: Brisbane | O20: Queensland | P20: Australia | Q20: Bikes | R20: Road Bikes | S20: Road-150 Red, 44 | T20: Red | U20: Road-150
E21: SO43756 | F21: 43756001 | G21: 1 | H21: 413.15 | I21: 699.1 | J21: 42924 | K21: 42933 | L21: 9 | M21: Cedric Liang | N21: London | O21: England | P21: United Kingdom | Q21: Bikes | R21: Road Bikes | S21: Road-650 Black, 58 | T21: Black | U21: Road-650
E22: SO43771 | F22: 43771001 | G22: 1 | H22: 413.15 | I22: 699.1 | J22: 42926 | K22: 42935 | L22: 9 | M22: Ashley Washington | N22: Long Beach | O22: California | P22: United States | Q22: Bikes | R22: Road Bikes | S22: Road-650 Red, 52 | T22: Red | U22: Road-650
... E69: SO43697 | F69: 43697001 | G69: 1 | H69: 2171.29 | I69: 3578.27 | J69: 42917 | K69: 42921 | L69: 4 | M69: Cole Watson | N69: Metchosin | O69: British Columbia | P69: Canada | Q69: Bikes | R69: Road Bikes | S69: Road-150 Red, 62 | T69: Red | U69: Road-150
E70: SO43702 | F70: 43702001 | G70: 1 | H70: 2171.29 | I70: 3578.27 | J70: 42917 | K70: 42921 | L70: 4 | M70: Colin Anand | O70: California | P70: United States | Q70: Bikes | R70: Road Bikes | S70: Road-150 Red, 44 | T70: Red | U70: Road-150
E71: SO43705 | F71: 43705001 | G71: 1 | H71: 1912.15 | I71: 3399.99 | J71: 42917 | K71: 42921 | L71: 4 | M71: Curtis Lu | N71: East Brisbane | O71: Queensland | P71: Australia | Q71: Bikes | R71: Mountain Bikes | S71: Mountain-100 Silver, 38 | T71: Silver | U71: Mountain-100
E72: SO43728 | F72: 43728001 | G72: 1 | H72: 2171.29 | I72: 3578.27 | J72: 42921 | K72: 42925 | L72: 4 | M72: Alyssa Garcia | N72: Fremont | O72: California | P72: United States | Q72: Bikes | R72: Road Bikes | S72: Road-150 Red, 52 | T72: Red | U72: Road-150
E73: SO43734 | F73: 43734001 | G73: 1 | H73: 2171.29 | I73: 3578.27 | J73: 42921 | K73: 42925 | L73: 4 | M73: Richard Brooks | N73: Port Orchard | O73: Washington | P73: United States | Q73: Bikes | R73: Road Bikes | S73: Road-150 Red, 48 | T73: Red | U73: Road-150
E74: SO43745 | F74: 43745001 | G74: 1 | H74: 2171.29 | I74: 3578.27 | J74: 42923 | K74: 42927 | L74: 4 | M74: Manuel Fernandez | N74: Malabar | O74: New South Wales | P74: Australia | Q74: Bikes | R74: Road Bikes | S74: Road-150 Red, 44 | T74: Red | U74: Road-150
E75: SO43749 | F75: 43749001 | G75: 1 | H75: 2171.29 | I75: 3578.27 | J75: 42923 | K75: 42927 | L75: 4 | M75: Paige Murphy | N75: Issaquah | O75: Washington | P75: United States | Q75: Bikes | R75: Road Bikes | S75: Road-150 Red, 56 | T75: Red | U75: Road-150
E76: SO43767 | F76: 43767001 | G76: 1 | H76: 1898.09 | I76: 3374.99 | J76: 42925 | K76: 42929 | L76: 4 | M76: Eugene Huang | N76: Seaford | O76: Victoria | P76: Australia | Q76: Bikes | R76: Mountain Bikes | S76: Mountain-100 Black, 44 | T76: Black | U76: Mountain-100
E77: SO43778 | F77: 43778001 | G77: 1 | H77: 1912.15 | I77: 3399.99 | J77: 42926 | K77: 42930 | L77: 4 | M77: Clarence Rai | N77: Bendigo | O77: Victoria | P77: Australia | Q77: Bikes | R77: Mountain Bikes | S77: Mountain-100 Silver, 42 | T77: Silver | U77: Mountain-100
E78: SO43786 | F78: 43786001 | G78: 1 | H78: 2171.29 | I78: 3578.27 | J78: 42928 | K78: 42932 | L78: 4 | M78: Clinton Moreno | N78: Paris | O78: Seine (Paris) | P78: France | Q78: Bikes | R78: Road Bikes | S78: Road-150 Red, 44 | T78: Red | U78: Road-150
E79: SO43789 | F79: 43789001 | G79: 1 | H79: 1898.09 | I79: 3374.99 | J79: 42928 | K79: 42932 | L79: 4 | M79: Tristan Butler | N79: Kirkland | O79: Washington | P79: United States | Q79: Bikes | R79: Mountain Bikes | S79: Mountain-100 Black, 48 | T79: Black | U79: Mountain-100
E80: SO43704 | F80: 43704001 | G80: 1 | H80: 1898.09 | I80: 3374.99 | J80: 42917 | K80: 42920 | L80: 3 | M80: Julio Ruiz | N80: East Brisbane | O80: Queensland | P80: Australia | Q80: Bikes | R80: Mountain Bikes | S80: Mountain-100 Black, 48 | T80: Black | U80: Mountain-100
E81: SO43708 | F81: 43708001 | G81: 1 | H81: 413.15 | I81: 699.1 | J81: 42918 | K81: 42921 | L81: 3 | M81: Brad Deng | N81: Liverpool | O81: England | P81: United Kingdom | Q81: Bikes | R81: Road Bikes | S81: Road-650 Red, 52 | T81: Red | U81: Road-650
E82: SO43740 | F82: 43740001 | G82: 1 | H82: 2171.29 | I82: 3578.27 | J82: 42922 | K82: 42925 | L82: 3 | M82: Cory Arun | N82: Milsons Point | O82: New South Wales | P82: Australia | Q82: Bikes | R82: Road Bikes | S82: Road-150 Red, 48 | T82: Red | U82: Road-150
... E106: SO43794 | F106: 43794001 | G106: 1 | H106: 1912.15 | I106: 3399.99 | J106: 42928 | K106: 42930 | L106: 2 | M106: Jimmy Moreno | N106: Bendigo | O106: Victoria | P106: Australia | Q106: Bikes | R106: Mountain Bikes | S106: Mountain-100 Silver, 48 | T106: Silver | U106: Mountain-100
